Workbook

Sheet Bens Imóveis
A2: SisTCE | B2: SisTCE | L2: SisTCE | M2: nrTombamento | N2: nrAfetacao | O2: diarioAfetacao | P2: tpEdificacao | Q2: endereco | R2: leiAfetacao | S2: situacaoUso | T2: codUnidadeOrcamentaria | U2: areaTerreno | V2: areaConstruida | W2: vlIncorporacao | X2: dtEntrada | Y2: dtUltimoInventario
A3: SIGLA UG | B3: UG - UNIDADE GESTORA | C3: FINALIDADE* | D3: ZONA* | E3: SITUAÇÃO* | F3: CARTÓRIO* | G3: MATRÍCULA* | H3: TERRENO VALOR (R$)* | I3: VALOR TOTAL (R$)* | J3: DATA DA REAVALIAÇÃO* | K3: DATA AFETAÇÃO* | L3: EDIFICAÇÃO VALOR (R$) | M3: Nº TOMBAMENTO | N3: Nº AFETAÇÃO | O3: DOM AFETAÇÃO | P3: TIPO DE EDIFICAÇÃO | Q3: ENDEREÇO | R3: LEI DE AFETAÇÃO | S3: SITUAÇÃO DE USO | T3: UNIDADE ORÇAMENTÁRIA | U3: ÁREA DO TERRENO (m²) | V3: ÁREA CONSTRUIDA (m²) | W3: VALOR INICIAL DO BEM (R$) | X3: DATA DE ENTRADA / INCORPORAÇÃO | Y3: DATA DO ÚLTIMO INVENTÁRIO
A4: SEMACC | B4: =VLOOKUP(A4,Listas!A$3:C$30,3,0) -> Secretaria Municipal de Agricultura, Abastecimento, Centro e Comércio Informal | C4: Anexo da Feira da Compensa | D4: OESTE | I4: =H4+L4 -> 0 | K4: Em ajuste | L4: 0 | M4: 86 | N4: Em ajuste | O4: Em ajuste | P4: Em ajuste | Q4: Av. Brasil, S/N - Compensa - CEP 69.036-110 | R4: Em ajuste | S4: Em ajuste | T4: =VLOOKUP(A4,Listas!A$3:C$30,2,0) -> 41101 | U4: Em ajuste | V4: Em ajuste | W4: Em ajuste | X4: Em ajuste | Y4: Em ajuste
A5: SEMACC | B5: =VLOOKUP(A5,Listas!A$3:C$30,3,0) -> Secretaria Municipal de Agricultura, Abastecimento, Centro e Comércio Informal | C5: Feira Comunitária Osvaldo Frota | D5: NORTE | I5: =H5+L5 -> 0 | K5: Em ajuste | L5: 0 | M5: 87 | N5: Em ajuste | O5: Em ajuste | P5: Em ajuste | Q5: Av. H, S/Nºº - Conjunto Américo Medeiros - Cidade Nova - CEP 69.000-000 | R5: Em ajuste | S5: Em ajuste | T5: =VLOOKUP(A5,Listas!A$3:C$30,2,0) -> 41101 | U5: Em ajuste | V5: Em ajuste | W5: Em ajuste | X5: Em ajuste | Y5: Em ajuste
A6: SEMACC | B6: =VLOOKUP(A6,Listas!A$3:C$30,3,0) -> Secretaria Municipal de Agricultura, Abastecimento, Centro e Comércio Informal | C6: Feira Comunitária Viver Melhor | D6: NORTE | F6: 1º OFÍCIO | G6: 59573 | I6: =H6+L6 -> 0 | K6: Em ajuste | L6: 0 | M6: 88 | N6: Em ajuste | O6: Em ajuste | P6: Em ajuste | Q6: Rua Ágata Azul, S/Nº° - Residencial Viver Melhor - Lago Azul - CEP 69.018-608 | R6: Em ajuste | S6: Em ajuste | T6: =VLOOKUP(A6,Listas!A$3:C$30,2,0) -> 41101 | U6: Em ajuste | V6: Em ajuste | W6: Em ajuste | X6: Em ajuste | Y6: Em ajuste
A7: SEMACC | B7: =VLOOKUP(A7,Listas!A$3:C$30,3,0) -> Secretaria Municipal de Agricultura, Abastecimento, Centro e Comércio Informal | C7: Feira do Mutirão | D7: NORTE | I7: =H7+L7 -> 0 | K7: Em ajuste | L7: 0 | M7: 89 | N7: Em ajuste | O7: Em ajuste | P7: Em ajuste | Q7: Rua Penetração III, S/Nºº - Amazonino Mendes - CEP 69.000-000 | R7: Em ajuste | S7: Em ajuste | T7: =VLOOKUP(A7,Listas!A$3:C$30,2,0) -> 41101 | U7: Em ajuste | V7: Em ajuste | W7: Em ajuste | X7: Em ajuste | Y7: Em ajuste
A8: SEMACC | B8: =VLOOKUP(A8,Listas!A$3:C$30,3,0) -> Secretaria Municipal de Agricultura, Abastecimento, Centro e Comércio Informal | C8: Feira e Praça Municipal Polivalente | D8: SUL | I8: =H8+L8 -> 0 | K8: Em ajuste | L8: 0 | M8: 90 | N8: Em ajuste | O8: Em ajuste | P8: Em ajuste | Q8: Av. Polivalente, S/Nºº - Japiim - ZONA Sul - CEP 69.078-260 | R8: Em ajuste | S8: Em ajuste | T8: =VLOOKUP(A8,Listas!A$3:C$30,2,0) -> 41101 | U8: Em ajuste | V8: Em ajuste | W8: Em ajuste | X8: Em ajuste | Y8: Em ajuste
A9: SEMACC | B9: =VLOOKUP(A9,Listas!A$3:C$30,3,0) -> Secretaria Municipal de Agricultura, Abastecimento, Centro e Comércio Informal | C9: Feira Municipal Cel. Jorge Teixeira - Manaus Moderna | D9: SUL | I9: =H9+L9 -> 0 | K9: Em ajuste | L9: 0 | M9: 91 | N9: Em ajuste | O9: Em ajuste | P9: Em ajuste | Q9: Rua Barão de São Domingos, 268 - Centro - CEP 69.005-010 | R9: Em ajuste | S9: Em ajuste | T9: =VLOOKUP(A9,Listas!A$3:C$30,2,0) -> 41101 | U9: Em ajuste | V9: Em ajuste | W9: Em ajuste | X9: Em ajuste | Y9: Em ajuste
A10: SEMACC | B10: =VLOOKUP(A10,Listas!A$3:C$30,3,0) -> Secretaria Municipal de Agricultura, Abastecimento, Centro e Comércio Informal | C10: Feira Municipal da Alvorada II | D10: CENTRO -OESTE | F10: 3º OFÍCIO | G10: 31726 | I10: =H10+L10 -> 0 | K10: Em ajuste | L10: 0 | M10: 92 | N10: Em ajuste | O10: Em ajuste | P10: Em ajuste | Q10: Av. J, S/Nºº - Alvorada II - CEP 69.000-000 | R10: Em ajuste | S10: Em ajuste | T10: =VLOOKUP(A10,Listas!A$3:C$30,2,0) -> 41101 | U10: Em ajuste | V10: Em ajuste | W10: Em ajuste | X10: Em ajuste | Y10: Em ajuste
A11: SEMACC | B11: =VLOOKUP(A11,Listas!A$3:C$30,3,0) -> Secretaria Municipal de Agricultura, Abastecimento, Centro e Comércio Informal | C11: Feira Municipal da Banana | D11: SUL | I11: =H11+L11 -> 0 | K11: Em ajuste | L11: 0 | M11: 93 | N11: Em ajuste | O11: Em ajuste | P11: Em ajuste | Q11: Rua Pedro Botelho, S/Nº° - Centro - CEP 69.005-100 | R11: Em ajuste | S11: Em ajuste | T11: =VLOOKUP(A11,Listas!A$3:C$30,2,0) -> 41101 | U11: Em ajuste | V11: Em ajuste | W11: Em ajuste | X11: Em ajuste | Y11: Em ajuste
A12: SEMACC | B12: =VLOOKUP(A12,Listas!A$3:C$30,3,0) -> Secretaria Municipal de Agricultura, Abastecimento, Centro e Comércio Informal | C12: Feira Municipal da Betânia | D12: SUL | I12: =H12+L12 -> 0 | K12: Em ajuste | L12: 0 | M12: 94 | N12: Em ajuste | O12: Em ajuste | P12: Em ajuste | Q12: Av. Adalberto Vale, S/Nº° - Betânia - CEP 69.000-000 | R12: Em ajuste | S12: Em ajuste | T12: =VLOOKUP(A12,Listas!A$3:C$30,2,0) -> 41101 | U12: Em ajuste | V12: Em ajuste | W12: Em ajuste | X12: Em ajuste | Y12: Em ajuste
A13: SEMACC | B13: =VLOOKUP(A13,Listas!A$3:C$30,3,0) -> Secretaria Municipal de Agricultura, Abastecimento, Centro e Comércio Informal | C13: Feira Municipal da Compensa II | D13: OESTE | I13: =H13+L13 -> 0 | K13: Em ajuste | L13: 0 | M13: 95 | N13: Em ajuste | O13: Em ajuste | P13: Em ajuste | Q13: Av. São Pedro, S/Nºº - Compensa II - CEP 69.000-000 | R13: Em ajuste | S13: Em ajuste | T13: =VLOOKUP(A13,Listas!A$3:C$30,2,0) -> 41101 | U13: Em ajuste | V13: Em ajuste | W13: Em ajuste | X13: Em ajuste | Y13: Em ajuste
A14: SEMACC | B14: =VLOOKUP(A14,Listas!A$3:C$30,3,0) -> Secretaria Municipal de Agricultura, Abastecimento, Centro e Comércio Informal | C14: Feira Municipal da Conquista | D14: LESTE | I14: =H14+L14 -> 0 | K14: Em ajuste | L14: 0 | M14: 96 | N14: Em ajuste | O14: Em ajuste | P14: Em ajuste | Q14: Av. Penetração, S/Nºº- Grande Vitória - CEP 69.000-000 | R14: Em ajuste | S14: Em ajuste | T14: =VLOOKUP(A14,Listas!A$3:C$30,2,0) -> 41101 | U14: Em ajuste | V14: Em ajuste | W14: Em ajuste | X14: Em ajuste | Y14: Em ajuste
A15: SEMACC | B15: =VLOOKUP(A15,Listas!A$3:C$30,3,0) -> Secretaria Municipal de Agricultura, Abastecimento, Centro e Comércio Informal | C15: Feira Municipal da Glória | D15: OESTE | F15: 3º OFÍCIO | G15: 29393 | I15: =H15+L15 -> 0 | K15: Em ajuste | L15: 0 | M15: 97 | N15: Em ajuste | O15: Em ajuste | P15: Em ajuste | Q15: Rua São Bento, S/Nºº - Glória - CEP 69.027-490 | R15: Em ajuste | S15: Em ajuste | T15: =VLOOKUP(A15,Listas!A$3:C$30,2,0) -> 41101 | U15: Em ajuste | V15: Em ajuste | W15: Em ajuste | X15: Em ajuste | Y15: Em ajuste
A16: SEMACC | B16: =VLOOKUP(A16,Listas!A$3:C$30,3,0) -> Secretaria Municipal de Agricultura, Abastecimento, Centro e Comércio Informal | C16: Feira Municipal da Japiinlândia | D16: SUL | I16: =H16+L16 -> 0 | K16: Em ajuste | L16: 0 | M16: 98 | N16: Em ajuste | O16: Em ajuste | P16: Em ajuste | Q16: Rua Portugal, S/Nº° - Japiinlândia - CEP 69.000-000 | R16: Em ajuste | S16: Em ajuste | T16: =VLOOKUP(A16,Listas!A$3:C$30,2,0) -> 41101 | U16: Em ajuste | V16: Em ajuste | W16: Em ajuste | X16: Em ajuste | Y16: Em ajuste
A17: SEMACC | B17: =VLOOKUP(A17,Listas!A$3:C$30,3,0) -> Secretaria Municipal de Agricultura, Abastecimento, Centro e Comércio Informal | C17: Feira Municipal da Maués | D17: SUL | I17: =H17+L17 -> 0 | K17: Em ajuste | L17: 0 | M17: 99 | N17: Em ajuste | O17: Em ajuste | P17: Em ajuste | Q17: Rua Maués, S/Nº° - Cachoeirinha - CEP 69.065-070 | R17: Em ajuste | S17: Em ajuste | T17: =VLOOKUP(A17,Listas!A$3:C$30,2,0) -> 41101 | U17: Em ajuste | V17: Em ajuste | W17: Em ajuste | X17: Em ajuste | Y17: Em ajuste
A18: SEMACC | B18: =VLOOKUP(A18,Listas!A$3:C$30,3,0) -> Secretaria Municipal de Agricultura, Abastecimento, Centro e Comércio Informal | C18: Feira Municipal da Nova Esperança | D18: LESTE | I18: =H18+L18 -> 0 | K18: Em ajuste | L18: 0 | M18: 100 | N18: Em ajuste | O18: Em ajuste | P18: Em ajuste | Q18: Rua Nova Esperança, S/Nº° - Colônia Antônio Aleixo - CEP 69.008-110 | R18: Em ajuste | S18: Em ajuste | T18: =VLOOKUP(A18,Listas!A$3:C$30,2,0) -> 41101 | U18: Em ajuste | V18: Em ajuste | W18: Em ajuste | X18: Em ajuste | Y18: Em ajuste
A19: SEMACC | B19: =VLOOKUP(A19,Listas!A$3:C$30,3,0) -> Secretaria Municipal de Agricultura, Abastecimento, Centro e Comércio Informal | C19: Feira Municipal da Panair | D19: SUL | I19: =H19+L19 -> 0 | K19: Em ajuste | L19: 0 | M19: 101 | N19: Em ajuste | O19: Em ajuste | P19: Em ajuste | Q19: Rua Bento José de Lima, S/Nºº - Educandos - CEP 69.000-000 | R19: Em ajuste | S19: Em ajuste | T19: =VLOOKUP(A19,Listas!A$3:C$30,2,0) -> 41101 | U19: Em ajuste | V19: Em ajuste | W19: Em ajuste | X19: Em ajuste | Y19: Em ajuste
A20: SEMACC | B20: =VLOOKUP(A20,Listas!A$3:C$30,3,0) -> Secretaria Municipal de Agricultura, Abastecimento, Centro e Comércio Informal | C20: Feira Municipal da Raiz | D20: SUL | I20: =H20+L20 -> 0 | K20: Em ajuste | L20: 0 | M20: 102 | N20: Em ajuste | O20: Em ajuste | P20: Em ajuste | Q20: Rua Delfim de Souza, S/Nºº - Raiz - CEP 69.068-020 | R20: Em ajuste | S20: Em ajuste | T20: =VLOOKUP(A20,Listas!A$3:C$30,2,0) -> 41101 | U20: Em ajuste | V20: Em ajuste | W20: Em ajuste | X20: Em ajuste | Y20: Em ajuste
A21: SEMACC | B21: =VLOOKUP(A21,Listas!A$3:C$30,3,0) -> Secretaria Municipal de Agricultura, Abastecimento, Centro e Comércio Informal | C21: Feira Municipal de São José II | D21: LESTE | I21: =H21+L21 -> 0 | K21: Em ajuste | L21: 0 | M21: 103 | N21: Em ajuste | O21: Em ajuste | P21: Em ajuste | Q21: Rua Raimundo Soares, S/Nºº - São José II - CEP 69.000-000 | R21: Em ajuste | S21: Em ajuste | T21: =VLOOKUP(A21,Listas!A$3:C$30,2,0) -> 41101 | U21: Em ajuste | V21: Em ajuste | W21: Em ajuste | X21: Em ajuste | Y21: Em ajuste
A22: SEMACC | B22: =VLOOKUP(A22,Listas!A$3:C$30,3,0) -> Secretaria Municipal de Agricultura, Abastecimento, Centro e Comércio Informal | C22: Feira Municipal do Armando Mendes | D22: LESTE | I22: =H22+L22 -> 0 | K22: Em ajuste | L22: 0 | M22: 104 | N22: Em ajuste | O22: Em ajuste | P22: Em ajuste | Q22: Rua Perimetral, S/Nºº - Armando Mendes - CEP 69.089-340 | R22: Em ajuste | S22: Em ajuste | T22: =VLOOKUP(A22,Listas!A$3:C$30,2,0) -> 41101 | U22: Em ajuste | V22: Em ajuste | W22: Em ajuste | X22: Em ajuste | Y22: Em ajuste
A23: SEMACC | B23: =VLOOKUP(A23,Listas!A$3:C$30,3,0) -> Secretaria Municipal de Agricultura, Abastecimento, Centro e Comércio Informal | C23: Feira Municipal do Bairro da Paz | D23: CENTRO -OESTE | I23: =H23+L23 -> 0 | K23: Em ajuste | L23: 0 | M23: 105 | N23: Em ajuste | O23: Em ajuste | P23: Em ajuste | Q23: Av. Esperança, S/Nºº - Bairro da Paz - CEP 69.000-000 | R23: Em ajuste | S23: Em ajuste | T23: =VLOOKUP(A23,Listas!A$3:C$30,2,0) -> 41101 | U23: Em ajuste | V23: Em ajuste | W23: Em ajuste | X23: Em ajuste | Y23: Em ajuste
A24: SEMACC | B24: =VLOOKUP(A24,Listas!A$3:C$30,3,0) -> Secretaria Municipal de Agricultura, Abastecimento, Centro e Comércio Informal | C24: Feira Municipal do Japiim | D24: SUL | I24: =H24+L24 -> 0 | K24: Em ajuste | L24: 0 | M24: 106 | N24: Em ajuste | O24: Em ajuste | P24: Em ajuste | Q24: Av. Rodrigo Otávio, S/Nºº - Japiim - CEP 69.000-000 | R24: Em ajuste | S24: Em ajuste | T24: =VLOOKUP(A24,Listas!A$3:C$30,2,0) -> 41101 | U24: Em ajuste | V24: Em ajuste | W24: Em ajuste | X24: Em ajuste | Y24: Em ajuste
A25: SEMACC | B25: =VLOOKUP(A25,Listas!A$3:C$30,3,0) -> Secretaria Municipal de Agricultura, Abastecimento, Centro e Comércio Informal | C25: Feira Municipal do Parque 10 | D25: CENTRO -SUL | I25: =H25+L25 -> 0 | K25: Em ajuste | L25: 0 | M25: 107 | N25: Em ajuste | O25: Em ajuste | P25: Em ajuste | Q25: Rua do Comércio, S/Nºº - Parque Dez - CEP 69.055-000 | R25: Em ajuste | S25: Em ajuste | T25: =VLOOKUP(A25,Listas!A$3:C$30,2,0) -> 41101 | U25: Em ajuste | V25: Em ajuste | W25: Em ajuste | X25: Em ajuste | Y25: Em ajuste
A26: SEMACC | B26: =VLOOKUP(A26,Listas!A$3:C$30,3,0) -> Secretaria Municipal de Agricultura, Abastecimento, Centro e Comércio Informal | C26: Feira Municipal do Produtor da Zona Leste | D26: LESTE | I26: =H26+L26 -> 0 | K26: Em ajuste | L26: 0 | M26: 108 | N26: Em ajuste | O26: Em ajuste | P26: Em ajuste | Q26: Rua Autaz Mirim, S/Nºº - Jorge Teixeira - CEP 69.088-245 | R26: Em ajuste | S26: Em ajuste | T26: =VLOOKUP(A26,Listas!A$3:C$30,2,0) -> 41101 | U26: Em ajuste | V26: Em ajuste | W26: Em ajuste | X26: Em ajuste | Y26: Em ajuste
A27: SEMACC | B27: =VLOOKUP(A27,Listas!A$3:C$30,3,0) -> Secretaria Municipal de Agricultura, Abastecimento, Centro e Comércio Informal | C27: Feira Municipal do Produtor de Santo Antônio | D27: OESTE | I27: =H27+L27 -> 0 | K27: Em ajuste | L27: 0 | M27: 109 | N27: Em ajuste | O27: Em ajuste | P27: Em ajuste | Q27: Rua São José, S/Nºº - Santo Antônio - CEP 69.000-000 | R27: Em ajuste | S27: Em ajuste | T27: =VLOOKUP(A27,Listas!A$3:C$30,2,0) -> 41101 | U27: Em ajuste | V27: Em ajuste | W27: Em ajuste | X27: Em ajuste | Y27: Em ajuste
... A32: SEMACC | B32: =VLOOKUP(A32,Listas!A$3:C$30,3,0) -> Secretaria Municipal de Agricultura, Abastecimento, Centro e Comércio Informal | C32: Feira Municipal Jardim dos Barés | D32: OESTE | I32: =H32+L32 -> 0 | K32: Em ajuste | L32: 0 | M32: 114 | N32: Em ajuste | O32: Em ajuste | P32: Em ajuste | Q32: Rua Jardim Botânico, S/Nº - São Jorge - CEP 69.000-000 | R32: Em ajuste | S32: Em ajuste | T32: =VLOOKUP(A32,Listas!A$3:C$30,2,0) -> 41101 | U32: Em ajuste | V32: Em ajuste | W32: Em ajuste | X32: Em ajuste | Y32: Em ajuste
A33: SEMACC | B33: =VLOOKUP(A33,Listas!A$3:C$30,3,0) -> Secretaria Municipal de Agricultura, Abastecimento, Centro e Comércio Informal | C33: Feira Municipal João Sena | D33: CENTRO -OESTE | F33: 3º OFÍCIO | G33: 31726 | I33: =H33+L33 -> 0 | K33: Em ajuste | L33: 0 | M33: 115 | N33: Em ajuste | O33: Em ajuste | P33: Em ajuste | Q33: Rua 07, S/Nº - Alvorada I - CEP 69.000-000 | R33: Em ajuste | S33: Em ajuste | T33: =VLOOKUP(A33,Listas!A$3:C$30,2,0) -> 41101 | U33: Em ajuste | V33: Em ajuste | W33: Em ajuste | X33: Em ajuste | Y33: Em ajuste
A34: SEMACC | B34: =VLOOKUP(A34,Listas!A$3:C$30,3,0) -> Secretaria Municipal de Agricultura, Abastecimento, Centro e Comércio Informal | C34: Feira Municipal Mundo Novo | D34: NORTE | I34: =H34+L34 -> 0 | K34: Em ajuste | L34: 0 | M34: 116 | N34: Em ajuste | O34: Em ajuste | P34: Em ajuste | Q34: Rua 07, S/Nº - Cidade Nova - CEP 69.000-000 | R34: Em ajuste | S34: Em ajuste | T34: =VLOOKUP(A34,Listas!A$3:C$30,2,0) -> 41101 | U34: Em ajuste | V34: Em ajuste | W34: Em ajuste | X34: Em ajuste | Y34: Em ajuste
A35: SEMACC | B35: =VLOOKUP(A35,Listas!A$3:C$30,3,0) -> Secretaria Municipal de Agricultura, Abastecimento, Centro e Comércio Informal | C35: Feira Municipal Nova Cidade | D35: NORTE | I35: =H35+L35 -> 0 | K35: Em ajuste | L35: 0 | M35: 117 | N35: Em ajuste | O35: Em ajuste | P35: Em ajuste | Q35: Av. Margarita, 1601 - Cidade Nova - CEP 69.097-207 | R35: Em ajuste | S35: Em ajuste | T35: =VLOOKUP(A35,Listas!A$3:C$30,2,0) -> 41101 | U35: Em ajuste | V35: Em ajuste | W35: Em ajuste | X35: Em ajuste | Y35: Em ajuste
A36: SEMACC | B36: =VLOOKUP(A36,Listas!A$3:C$30,3,0) -> Secretaria Municipal de Agricultura, Abastecimento, Centro e Comércio Informal | C36: Feira Municipal Pe. Rogerio Ruvoletto | D36: NORTE | I36: =H36+L36 -> 0 | K36: Em ajuste | L36: 0 | M36: 118 | N36: Em ajuste | O36: Em ajuste | P36: Em ajuste | Q36: Rua Samambaia, S/Nº - Santa Etelvina - CEP 69.059-500 | R36: Em ajuste | S36: Em ajuste | T36: =VLOOKUP(A36,Listas!A$3:C$30,2,0) -> 41101 | U36: Em ajuste | V36: Em ajuste | W36: Em ajuste | X36: Em ajuste | Y36: Em ajuste
A37: SEMACC | B37: =VLOOKUP(A37,Listas!A$3:C$30,3,0) -> Secretaria Municipal de Agricultura, Abastecimento, Centro e Comércio Informal | C37: Mercado Municipal Adolpho Lisboa | D37: SUL | I37: =H37+L37 -> 0 | K37: Em ajuste | L37: 0 | M37: 119 | N37: Em ajuste | O37: Em ajuste | P37: Em ajuste | Q37: Rua Dos Bares, S/Nº - Centro - CEP 69.005-020 | R37: Em ajuste | S37: Em ajuste | T37: =VLOOKUP(A37,Listas!A$3:C$30,2,0) -> 41101 | U37: Em ajuste | V37: Em ajuste | W37: Em ajuste | X37: Em ajuste | Y37: Em ajuste
A38: SEMACC | B38: =VLOOKUP(A38,Listas!A$3:C$30,3,0) -> Secretaria Municipal de Agricultura, Abastecimento, Centro e Comércio Informal | C38: Mercado Municipal Araújo Lima | D38: OESTE | F38: 3º OFÍCIO | G38: 29393 | I38: =H38+L38 -> 0 | K38: Em ajuste | L38: 0 | M38: 120 | N38: Em ajuste | O38: Em ajuste | P38: Em ajuste | Q38: Rua São Bento, S/Nºº - Glória - CEP 69.027-490 | R38: Em ajuste | S38: Em ajuste | T38: =VLOOKUP(A38,Listas!A$3:C$30,2,0) -> 41101 | U38: Em ajuste | V38: Em ajuste | W38: Em ajuste | X38: Em ajuste | Y38: Em ajuste
A39: SEMACC | B39: =VLOOKUP(A39,Listas!A$3:C$30,3,0) -> Secretaria Municipal de Agricultura, Abastecimento, Centro e Comércio Informal | C39: Mercado Municipal Carneiro da Mota | D39: SUL | I39: =H39+L39 -> 0 | K39: Em ajuste | L39: 0 | M39: 121 | N39: Em ajuste | O39: Em ajuste | P39: Em ajuste | Q39: Rua São Benedito, S/Nºº - Morro da Liberdade - CEP 69.000-000 | R39: Em ajuste | S39: Em ajuste | T39: =VLOOKUP(A39,Listas!A$3:C$30,2,0) -> 41101 | U39: Em ajuste | V39: Em ajuste | W39: Em ajuste | X39: Em ajuste | Y39: Em ajuste
A40: SEMACC | B40: =VLOOKUP(A40,Listas!A$3:C$30,3,0) -> Secretaria Municipal de Agricultura, Abastecimento, Centro e Comércio Informal | C40: Mercado Municipal Jorge de Moraes | D40: SUL | I40: =H40+L40 -> 0 | K40: Em ajuste | L40: 0 | M40: 122 | N40: Em ajuste | O40: Em ajuste | P40: Em ajuste | Q40: Av. Leopoldo Peres, S/Nºº - Educandos - CEP 69.000-000 | R40: Em ajuste | S40: Em ajuste | T40: =VLOOKUP(A40,Listas!A$3:C$30,2,0) -> 41101 | U40: Em ajuste | V40: Em ajuste | W40: Em ajuste | X40: Em ajuste | Y40: Em ajuste
A41: SEMACC | B41: =VLOOKUP(A41,Listas!A$3:C$30,3,0) -> Secretaria Municipal de Agricultura, Abastecimento, Centro e Comércio Informal | C41: Mini-Shopping - NAC da Compensa | D41: OESTE | I41: =H41+L41 -> 0 | K41: Em ajuste | L41: 0 | M41: 123 | N41: Em ajuste | O41: Em ajuste | P41: Em ajuste | Q41: Av. Brasil, 2470 - Compensa I - CEP 69.036-110 | R41: Em ajuste | S41: Em ajuste | T41: =VLOOKUP(A41,Listas!A$3:C$30,2,0) -> 41101 | U41: Em ajuste | V41: Em ajuste | W41: Em ajuste | X41: Em ajuste | Y41: Em ajuste
A42: SEMACC | B42: =VLOOKUP(A42,Listas!A$3:C$30,3,0) -> Secretaria Municipal de Agricultura, Abastecimento, Centro e Comércio Informal | C42: Sede SEMACC (Secretaria Municipal de Agricultura, Abastecimento, Centro e Comércio Informal | D42: SUL | I42: =H42+L42 -> 0 | K42: Em ajuste | L42: 0 | M42: 124 | N42: Em ajuste | O42: Em ajuste | P42: Em ajuste | Q42: Av. Carvalho Paes de Andrade, 140 - São Francisco - CEP 69.079-270 | R42: Em ajuste | S42: Em ajuste | T42: =VLOOKUP(A42,Listas!A$3:C$30,2,0) -> 41101 | U42: Em ajuste | V42: Em ajuste | W42: Em ajuste | X42: Em ajuste | Y42: Em ajuste
A43: SEMACC | B43: =VLOOKUP(A43,Listas!A$3:C$30,3,0) -> Secretaria Municipal de Agricultura, Abastecimento, Centro e Comércio Informal | C43: Unidade Agrícola do Pau Rosa | D43: RURAL | I43: =H43+L43 -> 0 | K43: Em ajuste | L43: 0 | M43: 125 | N43: Em ajuste | O43: Em ajuste | P43: Em ajuste | Q43: Rm. Pau Rosa, Km 15, 4 - BR 174 - Área Terrestre - CEP 69.000-000 | R43: Em ajuste | S43: Em ajuste | T43: =VLOOKUP(A43,Listas!A$3:C$30,2,0) -> 41101 | U43: Em ajuste | V43: Em ajuste | W43: Em ajuste | X43: Em ajuste | Y43: Em ajuste
A44: SEMACC | B44: =VLOOKUP(A44,Listas!A$3:C$30,3,0) -> Secretaria Municipal de Agricultura, Abastecimento, Centro e Comércio Informal | C44: Anexo do Departamento de Agricultura e Abastecimento (DAA) | D44: CENTRO-SUL | E44: DESATIVADO | F44: 1º OFÍCIO | G44: 57563 | I44: =H44+L44 -> 0 | K44: 44824 | L44: 0 | M44: 126 | N44: 004/2022 | O44: 5429 | P44: Em ajuste | Q44: R. Lima e Silva, 02 - Conjunto Mucuripe - Parque 10 de Novembro - CEP 69.055-717 | R44: Lei nº 3071, 15/06/2023 | S44: Em ajuste | T44: =VLOOKUP(A44,Listas!A$3:C$30,2,0) -> 41101 | U44: Em ajuste | V44: Em ajuste | W44: Em ajuste | X44: Em ajuste | Y44: Em ajuste
A45: SEMACC | B45: =VLOOKUP(A45,Listas!A$3:C$30,3,0) -> Secretaria Municipal de Agricultura, Abastecimento, Centro e Comércio Informal | C45: Feira Coberta do Alvorada I | D45: CENTRO-OESTE | E45: ATIVO | F45: 5º OFÍCIO | G45: 1635 | H45: 803602.42 | I45: =H45+L45 -> 3322558.2 | K45: Em ajuste | L45: 2518955.8 | M45: 127 | N45: Em ajuste | O45: Em ajuste | P45: Em ajuste | Q45: R. Rafael Assayag (antiga Rua 5), S/N - Alvorada I - CEP 69.043-130 | R45: Em ajuste | S45: Em ajuste | T45: =VLOOKUP(A45,Listas!A$3:C$30,2,0) -> 41101 | U45: Em ajuste | V45: Em ajuste | W45: Em ajuste | X45: Em ajuste | Y45: Em ajuste
...

Sheet Listas
A2: UG | B2: UNIDADE ORÇAMENTÁRIA | C2: SECRETARIA | D2: TIPO EDIFICAÇÃO | E2: ZONA | F2: SITUAÇÃO USO | G2: CARTÓRIO
A3: AGEMAN | B3: 70201 | C3: Agência Reguladora dos Serviços Públicos Delegados do Município de Manaus | D3: Casa | E3: Área Ribeirinha | F3: Cedido | G3: 1º Ofício
A4: CC | B4: 11101 | C4: Casa Civil | D4: Prédio | E4: Área Rural | F4: Compartilhado | G4: 2º Ofício
A5: CC-ERB | B5: 11103 | C5: Escritório de Representação em Brasília | D5: Terreno | E5: Centro-Oeste | F5: Ocioso | G5: 3º Ofício
A6: CGM | B6: 22101 | C6: Controladoria Geral do Municipio | D6: Em ajuste | E6: Centro-Sul | F6: Ocupado | G6: 4º Ofício
A7: CM | B7: 15101 | C7: Casa Militar | E7: Leste | F7: Subutilizado | G7: 5º Ofício
A8: CMM | B8: 01101 | C8: Câmara Municipal de Manaus | E8: Norte | F8: Em ajuste | G8: Em ajuste
A9: FDT | B9: 52301 | C9: Fundação Doutor Thomas | E9: Oeste
A10: FMS | B10: 23701 | C10: Fundo Municipal de Saúde | E10: Sul
A11: GVP | B11: 12101 | C11: Gabinete do Vice-Prefeito
A12: IMMU | B12: 58201 | C12: Instituto Municipal de Mobilidade Urbana
A13: IMPLURB | B13: 56201 | C13: Instituto Municipal de Planejamento Urbano
A14: MANAUSCULT | B14: 62301 | C14: Fundação Municipal de Cultura, Turismo e Eventos
A15: MANAUSPREV | B15: 63201 | C15: Manaus Previdência
A16: PGM | B16: 13101 | C16: Procuradoria Geral do Municipio
A17: SEMACC | B17: 41101 | C17: Secretaria Municipal de Agricultura, Abastecimento, Centro e Comércio Informal
A18: SEMAD | B18: 14101 | C18: Secretaria Municipal de Administração e Gestão
A19: SEMASC | B19: 37101 | C19: Secretaria Municipal da Mulher, Assistência Social e Cidadania
A20: SEMCOM | B20: 19101 | C20: Secretaria Municipal de Comunicação
A21: SEMED | B21: 18101 | C21: Secretaria Municipal de Educação
A22: SEMEF | B22: 16101 | C22: Secretaria Municipal de Finanças, Planejamento e Tecnologia da Informação
... A30: SEMULSP | B30: 38101 | C30: Secretaria Municipal de Limpeza Urbana
